[2024-08-21T19:39:55.861+0000] {taskinstance.py:1957} INFO - Dependencies all met for dep_context=non-requeueable deps ti=<TaskInstance: dados_climaticos.extrai_dados manual__2024-08-21T19:33:32.085372+00:00 [queued]>
[2024-08-21T19:39:55.870+0000] {taskinstance.py:1957} INFO - Dependencies all met for dep_context=requeueable deps ti=<TaskInstance: dados_climaticos.extrai_dados manual__2024-08-21T19:33:32.085372+00:00 [queued]>
[2024-08-21T19:39:55.871+0000] {taskinstance.py:2171} INFO - Starting attempt 1 of 1
[2024-08-21T19:39:55.885+0000] {taskinstance.py:2192} INFO - Executing <Task(PythonOperator): extrai_dados> on 2024-08-21 19:33:32.085372+00:00
[2024-08-21T19:39:55.890+0000] {standard_task_runner.py:60} INFO - Started process 73 to run task
[2024-08-21T19:39:55.894+0000] {standard_task_runner.py:87} INFO - Running: ['***', 'tasks', 'run', 'dados_climaticos', 'extrai_dados', 'manual__2024-08-21T19:33:32.085372+00:00', '--job-id', '117', '--raw', '--subdir', 'DAGS_FOLDER/dados_climaticos.py', '--cfg-path', '/tmp/tmphl9e4vuc']
[2024-08-21T19:39:55.896+0000] {standard_task_runner.py:88} INFO - Job 117: Subtask extrai_dados
[2024-08-21T19:39:55.942+0000] {task_command.py:423} INFO - Running <TaskInstance: dados_climaticos.extrai_dados manual__2024-08-21T19:33:32.085372+00:00 [running]> on host aaa07c95d172
[2024-08-21T19:39:56.016+0000] {taskinstance.py:2481} INFO - Exporting env vars: AIRFLOW_CTX_DAG_OWNER='***' AIRFLOW_CTX_DAG_ID='dados_climaticos' AIRFLOW_CTX_TASK_ID='extrai_dados' AIRFLOW_CTX_EXECUTION_DATE='2024-08-21T19:33:32.085372+00:00' AIRFLOW_CTX_TRY_NUMBER='1' AIRFLOW_CTX_DAG_RUN_ID='manual__2024-08-21T19:33:32.085372+00:00'
[2024-08-21T19:39:56.944+0000] {taskinstance.py:2699} ERROR - Task failed with exception
Traceback (most recent call last):
  File "/home/airflow/.local/lib/python3.8/site-packages/airflow/models/taskinstance.py", line 433, in _execute_task
    result = execute_callable(context=context, **execute_callable_kwargs)
  File "/home/airflow/.local/lib/python3.8/site-packages/airflow/operators/python.py", line 199, in execute
    return_value = self.execute_callable()
  File "/home/airflow/.local/lib/python3.8/site-packages/airflow/operators/python.py", line 216, in execute_callable
    return self.python_callable(*self.op_args, **self.op_kwargs)
  File "/opt/airflow/dags/dados_climaticos.py", line 38, in extrai_dados
    dados = pd.read_csv(URL)
  File "/home/airflow/.local/lib/python3.8/site-packages/pandas/io/parsers/readers.py", line 912, in read_csv
    return _read(filepath_or_buffer, kwds)
  File "/home/airflow/.local/lib/python3.8/site-packages/pandas/io/parsers/readers.py", line 577, in _read
    parser = TextFileReader(filepath_or_buffer, **kwds)
  File "/home/airflow/.local/lib/python3.8/site-packages/pandas/io/parsers/readers.py", line 1407, in __init__
    self._engine = self._make_engine(f, self.engine)
  File "/home/airflow/.local/lib/python3.8/site-packages/pandas/io/parsers/readers.py", line 1661, in _make_engine
    self.handles = get_handle(
  File "/home/airflow/.local/lib/python3.8/site-packages/pandas/io/common.py", line 716, in get_handle
    ioargs = _get_filepath_or_buffer(
  File "/home/airflow/.local/lib/python3.8/site-packages/pandas/io/common.py", line 368, in _get_filepath_or_buffer
    with urlopen(req_info) as req:
  File "/home/airflow/.local/lib/python3.8/site-packages/pandas/io/common.py", line 270, in urlopen
    return urllib.request.urlopen(*args, **kwargs)
  File "/usr/local/lib/python3.8/urllib/request.py", line 222, in urlopen
    return opener.open(url, data, timeout)
  File "/usr/local/lib/python3.8/urllib/request.py", line 531, in open
    response = meth(req, response)
  File "/usr/local/lib/python3.8/urllib/request.py", line 640, in http_response
    response = self.parent.error(
  File "/usr/local/lib/python3.8/urllib/request.py", line 569, in error
    return self._call_chain(*args)
  File "/usr/local/lib/python3.8/urllib/request.py", line 502, in _call_chain
    result = func(*args)
  File "/usr/local/lib/python3.8/urllib/request.py", line 649, in http_error_default
    raise HTTPError(req.full_url, code, msg, hdrs, fp)
urllib.error.HTTPError: HTTP Error 401: 
[2024-08-21T19:39:56.995+0000] {taskinstance.py:1138} INFO - Marking task as FAILED. dag_id=dados_climaticos, task_id=extrai_dados, execution_date=20240821T193332, start_date=20240821T193955, end_date=20240821T193956
[2024-08-21T19:39:57.014+0000] {standard_task_runner.py:107} ERROR - Failed to execute job 117 for task extrai_dados (HTTP Error 401: ; 73)
[2024-08-21T19:39:57.030+0000] {local_task_job_runner.py:234} INFO - Task exited with return code 1
[2024-08-21T19:39:57.045+0000] {taskinstance.py:3281} INFO - 0 downstream tasks scheduled from follow-on schedule check
