[2024-09-07T13:30:52.241+0000] {local_task_job_runner.py:123} INFO - ::group::Pre task execution logs
[2024-09-07T13:30:52.259+0000] {taskinstance.py:2612} INFO - Dependencies all met for dep_context=non-requeueable deps ti=<TaskInstance: selenium_test_dag.run_selenium_test scheduled__2024-09-06T00:00:00+00:00 [queued]>
[2024-09-07T13:30:52.267+0000] {taskinstance.py:2612} INFO - Dependencies all met for dep_context=requeueable deps ti=<TaskInstance: selenium_test_dag.run_selenium_test scheduled__2024-09-06T00:00:00+00:00 [queued]>
[2024-09-07T13:30:52.267+0000] {taskinstance.py:2865} INFO - Starting attempt 1 of 2
[2024-09-07T13:30:52.282+0000] {taskinstance.py:2888} INFO - Executing <Task(PythonOperator): run_selenium_test> on 2024-09-06 00:00:00+00:00
[2024-09-07T13:30:52.286+0000] {warnings.py:112} WARNING - /home/***/.local/lib/python3.12/site-packages/***/task/task_runner/standard_task_runner.py:70: DeprecationWarning: This process (pid=154) is multi-threaded, use of fork() may lead to deadlocks in the child.
  pid = os.fork()

[2024-09-07T13:30:52.288+0000] {standard_task_runner.py:72} INFO - Started process 155 to run task
[2024-09-07T13:30:52.288+0000] {standard_task_runner.py:104} INFO - Running: ['***', 'tasks', 'run', 'selenium_test_dag', 'run_selenium_test', 'scheduled__2024-09-06T00:00:00+00:00', '--job-id', '28', '--raw', '--subdir', 'DAGS_FOLDER/teste.py', '--cfg-path', '/tmp/tmp4qnkifd1']
[2024-09-07T13:30:52.289+0000] {standard_task_runner.py:105} INFO - Job 28: Subtask run_selenium_test
[2024-09-07T13:30:52.337+0000] {task_command.py:467} INFO - Running <TaskInstance: selenium_test_dag.run_selenium_test scheduled__2024-09-06T00:00:00+00:00 [running]> on host db526146b8a9
[2024-09-07T13:30:52.424+0000] {taskinstance.py:3131} INFO - Exporting env vars: AIRFLOW_CTX_DAG_OWNER='***' AIRFLOW_CTX_DAG_ID='selenium_test_dag' AIRFLOW_CTX_TASK_ID='run_selenium_test' AIRFLOW_CTX_EXECUTION_DATE='2024-09-06T00:00:00+00:00' AIRFLOW_CTX_TRY_NUMBER='1' AIRFLOW_CTX_DAG_RUN_ID='scheduled__2024-09-06T00:00:00+00:00'
[2024-09-07T13:30:52.427+0000] {taskinstance.py:731} INFO - ::endgroup::
[2024-09-07T13:30:52.505+0000] {taskinstance.py:3310} ERROR - Task failed with exception
Traceback (most recent call last):
  File "/home/airflow/.local/lib/python3.12/site-packages/airflow/models/taskinstance.py", line 767, in _execute_task
    result = _execute_callable(context=context, **execute_callable_kwargs)
             ^^^^^^^^^^^^^^^^^^^^^^^^^^^^^^^^^^^^^^^^^^^^^^^^^^^^^^^^^^^^^
  File "/home/airflow/.local/lib/python3.12/site-packages/airflow/models/taskinstance.py", line 733, in _execute_callable
    return ExecutionCallableRunner(
           ^^^^^^^^^^^^^^^^^^^^^^^^
  File "/home/airflow/.local/lib/python3.12/site-packages/airflow/utils/operator_helpers.py", line 252, in run
    return self.func(*args, **kwargs)
           ^^^^^^^^^^^^^^^^^^^^^^^^^^
  File "/home/airflow/.local/lib/python3.12/site-packages/airflow/models/baseoperator.py", line 406, in wrapper
    return func(self, *args, **kwargs)
           ^^^^^^^^^^^^^^^^^^^^^^^^^^^
  File "/home/airflow/.local/lib/python3.12/site-packages/airflow/operators/python.py", line 238, in execute
    return_value = self.execute_callable()
                   ^^^^^^^^^^^^^^^^^^^^^^^
  File "/home/airflow/.local/lib/python3.12/site-packages/airflow/operators/python.py", line 256, in execute_callable
    return runner.run(*self.op_args, **self.op_kwargs)
           ^^^^^^^^^^^^^^^^^^^^^^^^^^^^^^^^^^^^^^^^^^^
  File "/home/airflow/.local/lib/python3.12/site-packages/airflow/utils/operator_helpers.py", line 252, in run
    return self.func(*args, **kwargs)
           ^^^^^^^^^^^^^^^^^^^^^^^^^^
  File "/opt/airflow/dags/teste.py", line 15, in run_selenium_test
    driver = webdriver.Chrome(service=Service(), options=chrome_options)
             ^^^^^^^^^^^^^^^^^^^^^^^^^^^^^^^^^^^^^^^^^^^^^^^^^^^^^^^^^^^
  File "/home/airflow/.local/lib/python3.12/site-packages/selenium/webdriver/chrome/webdriver.py", line 45, in __init__
    super().__init__(
  File "/home/airflow/.local/lib/python3.12/site-packages/selenium/webdriver/chromium/webdriver.py", line 55, in __init__
    self.service.start()
  File "/home/airflow/.local/lib/python3.12/site-packages/selenium/webdriver/common/service.py", line 102, in start
    self.assert_process_still_running()
  File "/home/airflow/.local/lib/python3.12/site-packages/selenium/webdriver/common/service.py", line 115, in assert_process_still_running
    raise WebDriverException(f"Service {self._path} unexpectedly exited. Status code was: {return_code}")
selenium.common.exceptions.WebDriverException: Message: Service /home/airflow/.cache/selenium/chromedriver/linux64/128.0.6613.119/chromedriver unexpectedly exited. Status code was: 127

[2024-09-07T13:30:52.550+0000] {taskinstance.py:1225} INFO - Marking task as UP_FOR_RETRY. dag_id=selenium_test_dag, task_id=run_selenium_test, run_id=scheduled__2024-09-06T00:00:00+00:00, execution_date=20240906T000000, start_date=20240907T133052, end_date=20240907T133052
[2024-09-07T13:30:52.571+0000] {taskinstance.py:340} INFO - ::group::Post task execution logs
[2024-09-07T13:30:52.572+0000] {standard_task_runner.py:124} ERROR - Failed to execute job 28 for task run_selenium_test (Message: Service /home/airflow/.cache/selenium/chromedriver/linux64/128.0.6613.119/chromedriver unexpectedly exited. Status code was: 127
; 155)
Traceback (most recent call last):
  File "/home/airflow/.local/lib/python3.12/site-packages/airflow/task/task_runner/standard_task_runner.py", line 117, in _start_by_fork
    ret = args.func(args, dag=self.dag)
          ^^^^^^^^^^^^^^^^^^^^^^^^^^^^^
  File "/home/airflow/.local/lib/python3.12/site-packages/airflow/cli/cli_config.py", line 49, in command
    return func(*args, **kwargs)
           ^^^^^^^^^^^^^^^^^^^^^
  File "/home/airflow/.local/lib/python3.12/site-packages/airflow/utils/cli.py", line 115, in wrapper
    return f(*args, **kwargs)
           ^^^^^^^^^^^^^^^^^^
  File "/home/airflow/.local/lib/python3.12/site-packages/airflow/cli/commands/task_command.py", line 483, in task_run
    task_return_code = _run_task_by_selected_method(args, _dag, ti)
                       ^^^^^^^^^^^^^^^^^^^^^^^^^^^^^^^^^^^^^^^^^^^^
  File "/home/airflow/.local/lib/python3.12/site-packages/airflow/cli/commands/task_command.py", line 256, in _run_task_by_selected_method
    return _run_raw_task(args, ti)
           ^^^^^^^^^^^^^^^^^^^^^^^
  File "/home/airflow/.local/lib/python3.12/site-packages/airflow/cli/commands/task_command.py", line 341, in _run_raw_task
    return ti._run_raw_task(
           ^^^^^^^^^^^^^^^^^
  File "/home/airflow/.local/lib/python3.12/site-packages/airflow/utils/session.py", line 97, in wrapper
    return func(*args, session=session, **kwargs)
           ^^^^^^^^^^^^^^^^^^^^^^^^^^^^^^^^^^^^^^
  File "/home/airflow/.local/lib/python3.12/site-packages/airflow/models/taskinstance.py", line 3004, in _run_raw_task
    return _run_raw_task(
           ^^^^^^^^^^^^^^
  File "/home/airflow/.local/lib/python3.12/site-packages/airflow/models/taskinstance.py", line 273, in _run_raw_task
    TaskInstance._execute_task_with_callbacks(
  File "/home/airflow/.local/lib/python3.12/site-packages/airflow/models/taskinstance.py", line 3158, in _execute_task_with_callbacks
    result = self._execute_task(context, task_orig)
             ^^^^^^^^^^^^^^^^^^^^^^^^^^^^^^^^^^^^^^
  File "/home/airflow/.local/lib/python3.12/site-packages/airflow/models/taskinstance.py", line 3182, in _execute_task
    return _execute_task(self, context, task_orig)
           ^^^^^^^^^^^^^^^^^^^^^^^^^^^^^^^^^^^^^^^
  File "/home/airflow/.local/lib/python3.12/site-packages/airflow/models/taskinstance.py", line 767, in _execute_task
    result = _execute_callable(context=context, **execute_callable_kwargs)
             ^^^^^^^^^^^^^^^^^^^^^^^^^^^^^^^^^^^^^^^^^^^^^^^^^^^^^^^^^^^^^
  File "/home/airflow/.local/lib/python3.12/site-packages/airflow/models/taskinstance.py", line 733, in _execute_callable
    return ExecutionCallableRunner(
           ^^^^^^^^^^^^^^^^^^^^^^^^
  File "/home/airflow/.local/lib/python3.12/site-packages/airflow/utils/operator_helpers.py", line 252, in run
    return self.func(*args, **kwargs)
           ^^^^^^^^^^^^^^^^^^^^^^^^^^
  File "/home/airflow/.local/lib/python3.12/site-packages/airflow/models/baseoperator.py", line 406, in wrapper
    return func(self, *args, **kwargs)
           ^^^^^^^^^^^^^^^^^^^^^^^^^^^
  File "/home/airflow/.local/lib/python3.12/site-packages/airflow/operators/python.py", line 238, in execute
    return_value = self.execute_callable()
                   ^^^^^^^^^^^^^^^^^^^^^^^
  File "/home/airflow/.local/lib/python3.12/site-packages/airflow/operators/python.py", line 256, in execute_callable
    return runner.run(*self.op_args, **self.op_kwargs)
           ^^^^^^^^^^^^^^^^^^^^^^^^^^^^^^^^^^^^^^^^^^^
  File "/home/airflow/.local/lib/python3.12/site-packages/airflow/utils/operator_helpers.py", line 252, in run
    return self.func(*args, **kwargs)
           ^^^^^^^^^^^^^^^^^^^^^^^^^^
  File "/opt/airflow/dags/teste.py", line 15, in run_selenium_test
    driver = webdriver.Chrome(service=Service(), options=chrome_options)
             ^^^^^^^^^^^^^^^^^^^^^^^^^^^^^^^^^^^^^^^^^^^^^^^^^^^^^^^^^^^
  File "/home/airflow/.local/lib/python3.12/site-packages/selenium/webdriver/chrome/webdriver.py", line 45, in __init__
    super().__init__(
  File "/home/airflow/.local/lib/python3.12/site-packages/selenium/webdriver/chromium/webdriver.py", line 55, in __init__
    self.service.start()
  File "/home/airflow/.local/lib/python3.12/site-packages/selenium/webdriver/common/service.py", line 102, in start
    self.assert_process_still_running()
  File "/home/airflow/.local/lib/python3.12/site-packages/selenium/webdriver/common/service.py", line 115, in assert_process_still_running
    raise WebDriverException(f"Service {self._path} unexpectedly exited. Status code was: {return_code}")
selenium.common.exceptions.WebDriverException: Message: Service /home/airflow/.cache/selenium/chromedriver/linux64/128.0.6613.119/chromedriver unexpectedly exited. Status code was: 127

[2024-09-07T13:30:52.623+0000] {local_task_job_runner.py:266} INFO - Task exited with return code 1
[2024-09-07T13:30:52.638+0000] {taskinstance.py:3900} INFO - 0 downstream tasks scheduled from follow-on schedule check
[2024-09-07T13:30:52.644+0000] {local_task_job_runner.py:245} INFO - ::endgroup::
[2024-09-07T13:34:55.417+0000] {local_task_job_runner.py:123} INFO - ::group::Pre task execution logs
[2024-09-07T13:34:55.434+0000] {taskinstance.py:2612} INFO - Dependencies all met for dep_context=non-requeueable deps ti=<TaskInstance: selenium_test_dag.run_selenium_test scheduled__2024-09-06T00:00:00+00:00 [queued]>
[2024-09-07T13:34:55.442+0000] {taskinstance.py:2612} INFO - Dependencies all met for dep_context=requeueable deps ti=<TaskInstance: selenium_test_dag.run_selenium_test scheduled__2024-09-06T00:00:00+00:00 [queued]>
[2024-09-07T13:34:55.443+0000] {taskinstance.py:2865} INFO - Starting attempt 1 of 2
[2024-09-07T13:34:55.458+0000] {taskinstance.py:2888} INFO - Executing <Task(PythonOperator): run_selenium_test> on 2024-09-06 00:00:00+00:00
[2024-09-07T13:34:55.463+0000] {warnings.py:112} WARNING - /home/***/.local/lib/python3.12/site-packages/***/task/task_runner/standard_task_runner.py:70: DeprecationWarning: This process (pid=95) is multi-threaded, use of fork() may lead to deadlocks in the child.
  pid = os.fork()

[2024-09-07T13:34:55.465+0000] {standard_task_runner.py:72} INFO - Started process 96 to run task
[2024-09-07T13:34:55.465+0000] {standard_task_runner.py:104} INFO - Running: ['***', 'tasks', 'run', 'selenium_test_dag', 'run_selenium_test', 'scheduled__2024-09-06T00:00:00+00:00', '--job-id', '32', '--raw', '--subdir', 'DAGS_FOLDER/teste.py', '--cfg-path', '/tmp/tmpihdrrgtk']
[2024-09-07T13:34:55.467+0000] {standard_task_runner.py:105} INFO - Job 32: Subtask run_selenium_test
[2024-09-07T13:34:55.512+0000] {task_command.py:467} INFO - Running <TaskInstance: selenium_test_dag.run_selenium_test scheduled__2024-09-06T00:00:00+00:00 [running]> on host db526146b8a9
[2024-09-07T13:34:55.585+0000] {taskinstance.py:3131} INFO - Exporting env vars: AIRFLOW_CTX_DAG_OWNER='***' AIRFLOW_CTX_DAG_ID='selenium_test_dag' AIRFLOW_CTX_TASK_ID='run_selenium_test' AIRFLOW_CTX_EXECUTION_DATE='2024-09-06T00:00:00+00:00' AIRFLOW_CTX_TRY_NUMBER='1' AIRFLOW_CTX_DAG_RUN_ID='scheduled__2024-09-06T00:00:00+00:00'
[2024-09-07T13:34:55.586+0000] {taskinstance.py:731} INFO - ::endgroup::
[2024-09-07T13:34:55.651+0000] {taskinstance.py:3310} ERROR - Task failed with exception
Traceback (most recent call last):
  File "/home/airflow/.local/lib/python3.12/site-packages/airflow/models/taskinstance.py", line 767, in _execute_task
    result = _execute_callable(context=context, **execute_callable_kwargs)
             ^^^^^^^^^^^^^^^^^^^^^^^^^^^^^^^^^^^^^^^^^^^^^^^^^^^^^^^^^^^^^
  File "/home/airflow/.local/lib/python3.12/site-packages/airflow/models/taskinstance.py", line 733, in _execute_callable
    return ExecutionCallableRunner(
           ^^^^^^^^^^^^^^^^^^^^^^^^
  File "/home/airflow/.local/lib/python3.12/site-packages/airflow/utils/operator_helpers.py", line 252, in run
    return self.func(*args, **kwargs)
           ^^^^^^^^^^^^^^^^^^^^^^^^^^
  File "/home/airflow/.local/lib/python3.12/site-packages/airflow/models/baseoperator.py", line 406, in wrapper
    return func(self, *args, **kwargs)
           ^^^^^^^^^^^^^^^^^^^^^^^^^^^
  File "/home/airflow/.local/lib/python3.12/site-packages/airflow/operators/python.py", line 238, in execute
    return_value = self.execute_callable()
                   ^^^^^^^^^^^^^^^^^^^^^^^
  File "/home/airflow/.local/lib/python3.12/site-packages/airflow/operators/python.py", line 256, in execute_callable
    return runner.run(*self.op_args, **self.op_kwargs)
           ^^^^^^^^^^^^^^^^^^^^^^^^^^^^^^^^^^^^^^^^^^^
  File "/home/airflow/.local/lib/python3.12/site-packages/airflow/utils/operator_helpers.py", line 252, in run
    return self.func(*args, **kwargs)
           ^^^^^^^^^^^^^^^^^^^^^^^^^^
  File "/opt/airflow/dags/teste.py", line 15, in run_selenium_test
    driver = webdriver.Chrome(service=Service(), options=chrome_options)
             ^^^^^^^^^^^^^^^^^^^^^^^^^^^^^^^^^^^^^^^^^^^^^^^^^^^^^^^^^^^
  File "/home/airflow/.local/lib/python3.12/site-packages/selenium/webdriver/chrome/webdriver.py", line 45, in __init__
    super().__init__(
  File "/home/airflow/.local/lib/python3.12/site-packages/selenium/webdriver/chromium/webdriver.py", line 55, in __init__
    self.service.start()
  File "/home/airflow/.local/lib/python3.12/site-packages/selenium/webdriver/common/service.py", line 102, in start
    self.assert_process_still_running()
  File "/home/airflow/.local/lib/python3.12/site-packages/selenium/webdriver/common/service.py", line 115, in assert_process_still_running
    raise WebDriverException(f"Service {self._path} unexpectedly exited. Status code was: {return_code}")
selenium.common.exceptions.WebDriverException: Message: Service /home/airflow/.cache/selenium/chromedriver/linux64/128.0.6613.119/chromedriver unexpectedly exited. Status code was: 127

[2024-09-07T13:34:55.667+0000] {taskinstance.py:1225} INFO - Marking task as UP_FOR_RETRY. dag_id=selenium_test_dag, task_id=run_selenium_test, run_id=scheduled__2024-09-06T00:00:00+00:00, execution_date=20240906T000000, start_date=20240907T133455, end_date=20240907T133455
[2024-09-07T13:34:55.688+0000] {taskinstance.py:340} INFO - ::group::Post task execution logs
[2024-09-07T13:34:55.688+0000] {standard_task_runner.py:124} ERROR - Failed to execute job 32 for task run_selenium_test (Message: Service /home/airflow/.cache/selenium/chromedriver/linux64/128.0.6613.119/chromedriver unexpectedly exited. Status code was: 127
; 96)
Traceback (most recent call last):
  File "/home/airflow/.local/lib/python3.12/site-packages/airflow/task/task_runner/standard_task_runner.py", line 117, in _start_by_fork
    ret = args.func(args, dag=self.dag)
          ^^^^^^^^^^^^^^^^^^^^^^^^^^^^^
  File "/home/airflow/.local/lib/python3.12/site-packages/airflow/cli/cli_config.py", line 49, in command
    return func(*args, **kwargs)
           ^^^^^^^^^^^^^^^^^^^^^
  File "/home/airflow/.local/lib/python3.12/site-packages/airflow/utils/cli.py", line 115, in wrapper
    return f(*args, **kwargs)
           ^^^^^^^^^^^^^^^^^^
  File "/home/airflow/.local/lib/python3.12/site-packages/airflow/cli/commands/task_command.py", line 483, in task_run
    task_return_code = _run_task_by_selected_method(args, _dag, ti)
                       ^^^^^^^^^^^^^^^^^^^^^^^^^^^^^^^^^^^^^^^^^^^^
  File "/home/airflow/.local/lib/python3.12/site-packages/airflow/cli/commands/task_command.py", line 256, in _run_task_by_selected_method
    return _run_raw_task(args, ti)
           ^^^^^^^^^^^^^^^^^^^^^^^
  File "/home/airflow/.local/lib/python3.12/site-packages/airflow/cli/commands/task_command.py", line 341, in _run_raw_task
    return ti._run_raw_task(
           ^^^^^^^^^^^^^^^^^
  File "/home/airflow/.local/lib/python3.12/site-packages/airflow/utils/session.py", line 97, in wrapper
    return func(*args, session=session, **kwargs)
           ^^^^^^^^^^^^^^^^^^^^^^^^^^^^^^^^^^^^^^
  File "/home/airflow/.local/lib/python3.12/site-packages/airflow/models/taskinstance.py", line 3004, in _run_raw_task
    return _run_raw_task(
           ^^^^^^^^^^^^^^
  File "/home/airflow/.local/lib/python3.12/site-packages/airflow/models/taskinstance.py", line 273, in _run_raw_task
    TaskInstance._execute_task_with_callbacks(
  File "/home/airflow/.local/lib/python3.12/site-packages/airflow/models/taskinstance.py", line 3158, in _execute_task_with_callbacks
    result = self._execute_task(context, task_orig)
             ^^^^^^^^^^^^^^^^^^^^^^^^^^^^^^^^^^^^^^
  File "/home/airflow/.local/lib/python3.12/site-packages/airflow/models/taskinstance.py", line 3182, in _execute_task
    return _execute_task(self, context, task_orig)
           ^^^^^^^^^^^^^^^^^^^^^^^^^^^^^^^^^^^^^^^
  File "/home/airflow/.local/lib/python3.12/site-packages/airflow/models/taskinstance.py", line 767, in _execute_task
    result = _execute_callable(context=context, **execute_callable_kwargs)
             ^^^^^^^^^^^^^^^^^^^^^^^^^^^^^^^^^^^^^^^^^^^^^^^^^^^^^^^^^^^^^
  File "/home/airflow/.local/lib/python3.12/site-packages/airflow/models/taskinstance.py", line 733, in _execute_callable
    return ExecutionCallableRunner(
           ^^^^^^^^^^^^^^^^^^^^^^^^
  File "/home/airflow/.local/lib/python3.12/site-packages/airflow/utils/operator_helpers.py", line 252, in run
    return self.func(*args, **kwargs)
           ^^^^^^^^^^^^^^^^^^^^^^^^^^
  File "/home/airflow/.local/lib/python3.12/site-packages/airflow/models/baseoperator.py", line 406, in wrapper
    return func(self, *args, **kwargs)
           ^^^^^^^^^^^^^^^^^^^^^^^^^^^
  File "/home/airflow/.local/lib/python3.12/site-packages/airflow/operators/python.py", line 238, in execute
    return_value = self.execute_callable()
                   ^^^^^^^^^^^^^^^^^^^^^^^
  File "/home/airflow/.local/lib/python3.12/site-packages/airflow/operators/python.py", line 256, in execute_callable
    return runner.run(*self.op_args, **self.op_kwargs)
           ^^^^^^^^^^^^^^^^^^^^^^^^^^^^^^^^^^^^^^^^^^^
  File "/home/airflow/.local/lib/python3.12/site-packages/airflow/utils/operator_helpers.py", line 252, in run
    return self.func(*args, **kwargs)
           ^^^^^^^^^^^^^^^^^^^^^^^^^^
  File "/opt/airflow/dags/teste.py", line 15, in run_selenium_test
    driver = webdriver.Chrome(service=Service(), options=chrome_options)
             ^^^^^^^^^^^^^^^^^^^^^^^^^^^^^^^^^^^^^^^^^^^^^^^^^^^^^^^^^^^
  File "/home/airflow/.local/lib/python3.12/site-packages/selenium/webdriver/chrome/webdriver.py", line 45, in __init__
    super().__init__(
  File "/home/airflow/.local/lib/python3.12/site-packages/selenium/webdriver/chromium/webdriver.py", line 55, in __init__
    self.service.start()
  File "/home/airflow/.local/lib/python3.12/site-packages/selenium/webdriver/common/service.py", line 102, in start
    self.assert_process_still_running()
  File "/home/airflow/.local/lib/python3.12/site-packages/selenium/webdriver/common/service.py", line 115, in assert_process_still_running
    raise WebDriverException(f"Service {self._path} unexpectedly exited. Status code was: {return_code}")
selenium.common.exceptions.WebDriverException: Message: Service /home/airflow/.cache/selenium/chromedriver/linux64/128.0.6613.119/chromedriver unexpectedly exited. Status code was: 127

[2024-09-07T13:34:55.719+0000] {local_task_job_runner.py:266} INFO - Task exited with return code 1
[2024-09-07T13:34:55.735+0000] {taskinstance.py:3900} INFO - 0 downstream tasks scheduled from follow-on schedule check
[2024-09-07T13:34:55.738+0000] {local_task_job_runner.py:245} INFO - ::endgroup::
