[2024-09-08T12:12:55.313+0000] {local_task_job_runner.py:123} INFO - ::group::Pre task execution logs
[2024-09-08T12:12:55.328+0000] {taskinstance.py:2612} INFO - Dependencies all met for dep_context=non-requeueable deps ti=<TaskInstance: selenium_dag.run_selenium_task manual__2024-09-08T12:12:54.471382+00:00 [queued]>
[2024-09-08T12:12:55.335+0000] {taskinstance.py:2612} INFO - Dependencies all met for dep_context=requeueable deps ti=<TaskInstance: selenium_dag.run_selenium_task manual__2024-09-08T12:12:54.471382+00:00 [queued]>
[2024-09-08T12:12:55.336+0000] {taskinstance.py:2865} INFO - Starting attempt 1 of 2
[2024-09-08T12:12:55.351+0000] {taskinstance.py:2888} INFO - Executing <Task(PythonOperator): run_selenium_task> on 2024-09-08 12:12:54.471382+00:00
[2024-09-08T12:12:55.356+0000] {warnings.py:112} WARNING - /home/***/.local/lib/python3.12/site-packages/***/task/task_runner/standard_task_runner.py:70: DeprecationWarning: This process (pid=79) is multi-threaded, use of fork() may lead to deadlocks in the child.
  pid = os.fork()

[2024-09-08T12:12:55.358+0000] {standard_task_runner.py:72} INFO - Started process 80 to run task
[2024-09-08T12:12:55.357+0000] {standard_task_runner.py:104} INFO - Running: ['***', 'tasks', 'run', 'selenium_dag', 'run_selenium_task', 'manual__2024-09-08T12:12:54.471382+00:00', '--job-id', '89', '--raw', '--subdir', 'DAGS_FOLDER/teste.py', '--cfg-path', '/tmp/tmpirlmktr_']
[2024-09-08T12:12:55.358+0000] {standard_task_runner.py:105} INFO - Job 89: Subtask run_selenium_task
[2024-09-08T12:12:55.446+0000] {task_command.py:467} INFO - Running <TaskInstance: selenium_dag.run_selenium_task manual__2024-09-08T12:12:54.471382+00:00 [running]> on host d5d458c7d440
[2024-09-08T12:12:55.523+0000] {taskinstance.py:3131} INFO - Exporting env vars: AIRFLOW_CTX_DAG_OWNER='***' AIRFLOW_CTX_DAG_ID='selenium_dag' AIRFLOW_CTX_TASK_ID='run_selenium_task' AIRFLOW_CTX_EXECUTION_DATE='2024-09-08T12:12:54.471382+00:00' AIRFLOW_CTX_TRY_NUMBER='1' AIRFLOW_CTX_DAG_RUN_ID='manual__2024-09-08T12:12:54.471382+00:00'
[2024-09-08T12:12:55.524+0000] {taskinstance.py:731} INFO - ::endgroup::
[2024-09-08T12:15:07.173+0000] {connectionpool.py:870} WARNING - Retrying (Retry(total=2, connect=None, read=None, redirect=None, status=None)) after connection broken by 'ConnectTimeoutError(<urllib3.connection.HTTPConnection object at 0x7ff0aae45b80>, 'Connection to 172.22.0.3 timed out. (connect timeout=None)')': /wd/hub/session
[2024-09-08T12:17:20.288+0000] {connectionpool.py:870} WARNING - Retrying (Retry(total=1, connect=None, read=None, redirect=None, status=None)) after connection broken by 'ConnectTimeoutError(<urllib3.connection.HTTPConnection object at 0x7ff0aae47800>, 'Connection to 172.22.0.3 timed out. (connect timeout=None)')': /wd/hub/session
[2024-09-08T12:19:33.413+0000] {connectionpool.py:870} WARNING - Retrying (Retry(total=0, connect=None, read=None, redirect=None, status=None)) after connection broken by 'ConnectTimeoutError(<urllib3.connection.HTTPConnection object at 0x7ff0aae47d70>, 'Connection to 172.22.0.3 timed out. (connect timeout=None)')': /wd/hub/session
